Workbook

Sheet List
A1: order | B1: YY | C1: MM | D1: DD | E1: P.O. No. | F1: Container No. | G1: Container Seal No. | H1: Lot No. | I1: Receiving Date | J1: Product Description | K1: Supplier | L1: Truck Line
B2: 26 | H2: =IF(D2="","","GIN"&MID(B2,2,1)&MID(B2,1,1)&MID(C2,2,1)&MID(C2,1,1)&MID(D2,2,1)&MID(D2,1,1)&A2) | I2: =IF(D2="","",DATE(B2,C2,D2)) | J2: FRESH GINGER | K2: Santao | L2: SL
B3: 26 | H3: =IF(D3="","","GIN"&MID(B3,2,1)&MID(B3,1,1)&MID(C3,2,1)&MID(C3,1,1)&MID(D3,2,1)&MID(D3,1,1)&A3) | I3: =IF(D3="","",DATE(B3,C3,D3)) | J3: FRESH GINGER | K3: Santao | L3: SL
B4: 26 | C4: 04 | H4: =IF(D4="","","GIN"&MID(B4,2,1)&MID(B4,1,1)&MID(C4,2,1)&MID(C4,1,1)&MID(D4,2,1)&MID(D4,1,1)&A4) | I4: =IF(D4="","",DATE(B4,C4,D4)) | J4: FRESH GINGER | K4: Santao | L4: SL
B5: 26 | C5: 04 | H5: =IF(D5="","","PGIN"&MID(B5,2,1)&MID(B5,1,1)&MID(C5,2,1)&MID(C5,1,1)&MID(D5,2,1)&MID(D5,1,1)&A5) | I5: =IF(D5="","",DATE(B5,C5,D5)) | J5: FRESH GINGER | K5: Santao | L5: SL
B6: 26 | C6: 04 | H6: =IF(D6="","","PGIN"&MID(B6,2,1)&MID(B6,1,1)&MID(C6,2,1)&MID(C6,1,1)&MID(D6,2,1)&MID(D6,1,1)&A6) | I6: =IF(D6="","",DATE(B6,C6,D6)) | J6: FRESH GINGER | K6: Santao | L6: SL
B7: 26 | C7: 04 | H7: =IF(D7="","","PGIN"&MID(B7,2,1)&MID(B7,1,1)&MID(C7,2,1)&MID(C7,1,1)&MID(D7,2,1)&MID(D7,1,1)&A7) | I7: =IF(D7="","",DATE(B7,C7,D7)) | J7: FRESH GINGER | K7: Santao | L7: SL
B8: 26 | C8: 04 | H8: =IF(D8="","","PGIN"&MID(B8,2,1)&MID(B8,1,1)&MID(C8,2,1)&MID(C8,1,1)&MID(D8,2,1)&MID(D8,1,1)&A8) | I8: =IF(D8="","",DATE(B8,C8,D8)) | J8: FRESH GINGER | K8: Santao | L8: SL
B9: 26 | C9: 04 | H9: =IF(D9="","","PGIN"&MID(B9,2,1)&MID(B9,1,1)&MID(C9,2,1)&MID(C9,1,1)&MID(D9,2,1)&MID(D9,1,1)&A9) | I9: =IF(D9="","",DATE(B9,C9,D9)) | J9: FRESH GINGER | K9: Santao | L9: SL
B10: 26 | C10: 04 | H10: =IF(D10="","","PGIN"&MID(B10,2,1)&MID(B10,1,1)&MID(C10,2,1)&MID(C10,1,1)&MID(D10,2,1)&MID(D10,1,1)&A10) | I10: =IF(D10="","",DATE(B10,C10,D10)) | J10: FRESH GINGER | K10: Santao | L10: SL

Sheet Warehouse Receiving Manifest
A1: Trinity Distribution Inc. | L1: Warehouse Receiving Manifest
H2: Frozen | I2: Cooler | J2: Dry
A3: =List!F2 -> 0 | E3: =List!G2 -> 0 | I3: X | L3: Cesar | N3: =List!I2
A4: Container No. | E4: Container Seal No. | L4: Receiver | N4: Receiving Date:
H5: Temp. Recorder(s)
B6: TDI | E6: =List!E2 -> 0 | L6: Inspect By | N6: Unloading Date:
A7: For Account Of: | E7: P.O. No.
D9: Item/Net Weight | F9: 1 | G9: 2 | H9: 3 | I9: 4 | J9: 5 | K9: 6 | L9: 7 | M9: 8 | N9: 9 | O9: 10
A10: =List!L2 -> SL | D10: =D15 -> 600000
A11: Delivering Truck Line:
A14: Lot No. | D14: Item Code: | F14: Product Description: | I14: Pack Size: | J14: Origin: | K14: Supplier: | M14: Product Temp | N14: Total Cases:
A15: =List!H2 | D15: 600000 | F15: =List!J2 -> FRESH GINGER | I15: 30LBS | J15: China | K15: =List!K2 -> Santao
A16: 1 | B16: 2 | C16: 3 | D16: 9 | E16: 5 | F16: 6 | G16: 7 | H16: 8 | I16: 9 | J16: 10 | K16: 11 | L16: 12 | M16: 13 | N16: 14 | O16: 15
A17: 16 | B17: 17 | C17: 18 | D17: 19 | E17: 20 | F17: 21 | G17: 22 | H17: 23 | I17: 24 | J17: 25 | K17: 26 | L17: 27 | M17: 28 | N17: 29 | O17: 30
A18: 31 | B18: 32 | C18: 33 | D18: 34 | E18: 35 | F18: Cooler/Freezer Location: | H18: Cases Per Layer: | I18: Product Quality: | K18: Off-odor: | L18: Packaging: | M18: Labelling: | N18: Foreign Material: | O18: Damage Case(s):
A21: Lot No. | D21: Item Code: | F21: Product Description: | I21: Pack Size: | J21: Origin: | K21: Supplier: | M21: Product Temp | N21: Total Cases:
A23: 1 | B23: 2 | C23: 3 | D23: 4 | E23: 5 | F23: 6 | G23: 7 | H23: 8 | I23: 9 | J23: 10 | K23: 11 | L23: 12 | M23: 13 | N23: 14 | O23: 15
A24: 16 | B24: 17 | C24: 18 | D24: 19 | E24: 20 | F24: 21 | G24: 22 | H24: 23 | I24: 24 | J24: 25 | K24: 26 | L24: 27 | M24: 28 | N24: 29 | O24: 30
A25: 31 | B25: 32 | C25: 33 | D25: 34 | E25: 35 | F25: Cooler/Freezer Location: | H25: Cases Per Layer: | I25: Product Quality: | K25: Off-odor: | L25: Packaging: | M25: Labelling: | N25: Foreign Material: | O25: Damage Case(s):
A28: Lot No. | D28: Item Code: | F28: Product Description: | I28: Pack Size: | J28: Origin: | K28: Supplier: | M28: Product Temp | N28: Total Cases:
A30: 1 | B30: 2 | C30: 3 | D30: 4 | E30: 5 | F30: 6 | G30: 7 | H30: 8 | I30: 9 | J30: 10 | K30: 11 | L30: 12 | M30: 13 | N30: 14 | O30: 15
A31: 16 | B31: 17 | C31: 18 | D31: 19 | E31: 20 | F31: 21 | G31: 22 | H31: 23 | I31: 24 | J31: 25 | K31: 26 | L31: 27 | M31: 28 | N31: 29 | O31: 30
A32: 31 | B32: 32 | C32: 33 | D32: 34 | E32: 35 | F32: Cooler/Freezer Location: | H32: Cases Per Layer: | I32: Product Quality: | K32: Off-odor: | L32: Packaging: | M32: Labelling: | N32: Foreign Material: | O32: Damage Case(s):
A35: Qualify uses "Ö" or YES . Disqualify uses "X" or NO. If there's any disqualification, please indicate the finding(s) and corrective actions in the Corrective Action Form.
A36: Trinity Distribution Inc. | L36: Warehouse Receiving Manifest
H37: Frozen | I37: Cooler | J37: Dry
A38: =List!F3 -> 0 | E38: =List!G3 -> 0 | I38: X | L38: Cesar | N38: =List!I3
A39: Container No. | E39: Container Seal No. | L39: Receiver | N39: Receiving Date:
H40: Temp. Recorder(s)
B41: TDI | E41: =List!E3 -> 0 | L41: Inspect By | N41: Unloading Date:
A42: For Account Of: | E42: P.O. No.
D44: Item/Net Weight | F44: 1 | G44: 2 | H44: 3 | I44: 4 | J44: 5 | K44: 6 | L44: 7 | M44: 8 | N44: 9 | O44: 10
A45: =List!L3 -> SL | D45: 600000
A46: Delivering Truck Line:
A49: Lot No. | D49: Item Code: | F49: Product Description: | I49: Pack Size: | J49: Origin: | K49: Supplier: | M49: Product Temp | N49: Total Cases:
A50: =List!H3 | D50: 600000 | F50: =List!J3 -> FRESH GINGER | I50: 30LBS | J50: China | K50: =List!K3 -> Santao
A51: 1 | B51: 2 | C51: 3 | D51: 9 | E51: 5 | F51: 6 | G51: 7 | H51: 8 | I51: 9 | J51: 10 | K51: 11 | L51: 12 | M51: 13 | N51: 14 | O51: 15
A52: 16 | B52: 17 | C52: 18 | D52: 19 | E52: 20 | F52: 21 | G52: 22 | H52: 23 | I52: 24 | J52: 25 | K52: 26 | L52: 27 | M52: 28 | N52: 29 | O52: 30
A53: 31 | B53: 32 | C53: 33 | D53: 34 | E53: 35 | F53: Cooler/Freezer Location: | H53: Cases Per Layer: | I53: Product Quality: | K53: Off-odor: | L53: Packaging: | M53: Labelling: | N53: Foreign Material: | O53: Damage Case(s):
A56: Lot No. | D56: Item Code: | F56: Product Description: | I56: Pack Size: | J56: Origin: | K56: Supplier: | M56: Product Temp | N56: Total Cases:
...

Sheet Ginger Report
A1: Trinity Distribution Inc. | H1: Ginger Report
A2: =List!F2 -> 0 | D2: =List!E2 -> 0
A3: Container No. | D3: P.O. No. | G3: Receiving Date: | J3: Reporter
A5: Lot No. | C5: Item Code: | E5: Product Description: | H5: Pack Size: | I5: Origin: | J5: Supplier:
A6: =List!H2 | C6: 600000 | E6: =List!J2 -> FRESH GINGER | H6: 1/30# | I6: China | J6: =List!K2 -> Santao
A7: Gross weight(≥35LBS) | B7: 1 | C7: 2 | D7: 3 | E7: 4 | F7: 5 | G7: 6 | H7: 7 | I7: 8 | J7: 9 | K7: 10
A8: Wet with plastic bag
A9: Dry packed
A11: Quality (Disqualified use 'NO.') | B11: 1 | C11: 2 | D11: 3 | E11: 4 | F11: 5 | G11: 6 | H11: 7 | I11: 8 | J11: 9 | K11: 10
A12: Mold
A13: Rotten
A14: Sprouting
A15: Not Clean washed
A16: Skin off
A17: Small piece
A18: Green color
A19: Dirty on the box
A20: Lot No. | C20: Item Code: | E20: Product Description: | H20: Pack Size: | I20: Origin: | J20: Supplier:
A22: Gross weight(≥35LBS) | B22: 1 | C22: 2 | D22: 3 | E22: 4 | F22: 5 | G22: 6 | H22: 7 | I22: 8 | J22: 9 | K22: 10
A23: Wet with plastic bag
A24: Dry packed
A26: Quality (Disqualified use 'NO.') | B26: 1 | C26: 2 | D26: 3 | E26: 4 | F26: 5 | G26: 6 | H26: 7 | I26: 8 | J26: 9 | K26: 10
A27: Mold
A28: Rotten
A29: Sprouting
A30: Not Clean washed
A31: Skin off
A32: Small piece
A33: Green color
A34: Dirty on the box
A35: Trinity Distribution Inc. | H35: Ginger Report
A36: =List!F3 -> 0 | D36: =List!E3 -> 0
A37: Container No. | D37: P.O. No. | G37: Receiving Date: | J37: Reporter
A39: Lot No. | C39: Item Code: | E39: Product Description: | H39: Pack Size: | I39: Origin: | J39: Supplier:
A40: =List!H3 | C40: 600000 | E40: =List!J3 -> FRESH GINGER | H40: 1/30# | I40: China | J40: =List!K3 -> Santao
A41: Gross weight(≥35LBS) | B41: 1 | C41: 2 | D41: 3 | E41: 4 | F41: 5 | G41: 6 | H41: 7 | I41: 8 | J41: 9 | K41: 10
A42: Wet with plastic bag
A43: Dry packed
A45: Quality (Disqualified use 'NO.') | B45: 1 | C45: 2 | D45: 3 | E45: 4 | F45: 5 | G45: 6 | H45: 7 | I45: 8 | J45: 9 | K45: 10
A46: Mold
...

Sheet label
A1: Date: | B1: =List!I2
A2: ='Warehouse Receiving Manifest'!F15 -> FRESH GINGER
A3: =List!E2 -> 0
A4: =List!H2
A5: Pallet#
A6: Date: | B6: =List!I3
A7: =List!J3 -> FRESH GINGER
A8: =List!E3 -> 0
A9: =List!H3
A10: Pallet#
A11: Date: | B11: =List!I4
A12: =List!J4 -> FRESH GINGER
A13: =List!E4 -> 0
A14: =List!H4
A15: Pallet#
A16: Date: | B16: =List!I5
A17: =List!J5 -> FRESH GINGER
A18: =List!E5 -> 0
A19: =List!H5
A20: Pallet#
A21: Date: | B21: =List!I6
A22: =List!J6 -> FRESH GINGER
A23: =List!E6 -> 0
A24: =List!H6
A25: Pallet#
A26: Date: | B26: =List!I7
A27: =List!J7 -> FRESH GINGER
A28: =List!E7 -> 0
A29: =List!H7
A30: Pallet#
A31: Date: | B31: =List!I8
A32: =List!J8 -> FRESH GINGER
A33: =List!E8 -> 0
A34: =List!H8
A35: Pallet#
A36: Date: | B36: =List!I9
A37: =List!J9 -> FRESH GINGER
A38: =List!E9 -> 0
A39: =List!H9
A40: Pallet#
...

Sheet ginger supplier
A1: Item | B1: Suplier
A2: Fresh Organic Ginger, Peru. 30# | B2: COAAM
A3: Fresh Ginger, Thailand. 1/30# | B3: J&P
A4: Fresh Organic Ginger, Peru. 1/30# | B4: JCH
A5: Fresh Organic Ginger, Peru.1/40# | B5: JCH
A6: Fresh Ginger, Chinese Varity | B6: Jungle Fresh
A7: Fresh Organic Ginger, Peru. 1/30# | B7: Jungle Fresh
A8: Fresh Ginger, Thailand. 1/30# | B8: KOR
A9: Fresh Ginger, China. 1/30# | B9: LAIWU TAIFENG
A10: Fresh Organic Ginger, Peru. 1/30# | B10: LEON
A11: Fresh Ginger, China. 1/30# 1,872 | B11: MANHING
A12: Fresh Organic Ginger, Peru. 1/30# | B12: Nativa
... A28: PLASTIC BAGS-11PC | B28: SANTAO
